Workbook

Sheet AZ6 RZ1 (ACCIDENT)
O2: Sección transversal efectiva (σ) en barns | V2: Incremental Failure - Accident | X2: Heavy Metal Accident Release | Z2: Fuel Particle Kernel [Non-Intact Accident Release] | AB2: Diffusive Release through Fuel Particle Coatings [Intact Accident Release] | AD2: Graphite (Compact Matrix and Fuel Element) | AF2: FLIBE | AH2: Reactor Building | AJ2: Termino fuente mecanicista (S) (bq) | AM2: =B3 -> Isotopo | AO2: AF 50% | AX2: AF 95%
B3: Isotopo | C3: Isotope [ZZAAA] | D3: Tipo de isotopo | E3: Number Density [atom/b/cm] | F3: Vida Media (Laraweb) — sustituida por NUBASE2020 | G3: Vida Media (copilot) — sustituida por NUBASE2020 | H3: Vida Media (chatGPT) — sustituida por NUBASE2020 | I3: Vida Media (años) | J3: Vida Media (dias) | K3: Vida Media (horas) | L3: Vida Media (minutos) | M3: Sec | N3: Constante de desintegración (λ) | O3: Barn (cm2) a cm | P3: Volumen (cm2) | Q3: Densidad atomica (atom/cm3) | R3: Nº atomos | S3: Actividad (bq) | T3: Actividad (Ci) | U3: Tipo de isotopos | V3: 0.5 | W3: 0.95 | X3: AFHMC 50% | Y3: AFHMC 95% | Z3: AFK 50% | AA3: AFK 95% | AB3: AFDiff 50% | AC3: AFDiff 95% | AD3: AFG 50% | AE3: AFG 95% | AF3: AFFLIBE 50% | AG3: AFFLIBE 95% | AH3: AFRB 50% | AI3: AFRB 95% | AJ3: AF 50% | AK3: AF 95% | AO3: Core Activity | AP3: HMC | AQ3: Kernel | AR3: Diff | AS3: Graphite | AT3: FLIBE | AU3: Reactor Building | AX3: Core Activity | AY3: HMC | AZ3: Kernel | BA3: Diff | BB3: Graphite | BC3: FLIBE | BD3: Reactor Building | BF3: T½ NUBASE2020 | BG3: T½ NUBASE2020 (s) | BH3: Nombre anterior (corregido) | BI3: Grupo químico corregido
B4: C-12 | C4: 6012 | E4: 0.0118211 | G4: Estable | H4: Estable | M4: =IF(ISNUMBER(BG4),BG4,"") | N4: =IF(ISNUMBER(M4),LN(2)/M4,0) -> 0 | O4: =10^-24 -> 1e-24 | P4: =PI()*$K$97^2*$K$98 -> 13978831 | Q4: =E4/O4 -> 1.18211e+22 | R4: =Q4*P4 -> 1.6524516e+29 | S4: =R4*N4 -> 0 | X4: 0.01 | Z4: 0.999 | AJ4: =S4*X4*(1-Z4) -> 0 | BF4: estable
B5: O-16 | C5: 8016 | E5: 0.0354634 | G5: Estable | H5: Estable | M5: =IF(ISNUMBER(BG5),BG5,"") | N5: =IF(ISNUMBER(M5),LN(2)/M5,0) -> 0 | O5: =10^-24 -> 1e-24 | P5: =PI()*$K$97^2*$K$98 -> 13978831 | Q5: =E5/O5 -> 3.54634e+22 | R5: =Q5*P5 -> 4.9573686e+29 | S5: =R5*N5 -> 0 | X5: 0.01 | Z5: 0.999 | AJ5: =S5*X5*(1-Z5) -> 0 | BF5: estable
B6: Kr-83 | C6: 36083 | E6: 1.00841e-05 | G6: Estable | H6: Estable | M6: =IF(ISNUMBER(BG6),BG6,"") | N6: =IF(ISNUMBER(M6),LN(2)/M6,0) -> 0 | O6: =10^-24 -> 1e-24 | P6: =PI()*$K$97^2*$K$98 -> 13978831 | Q6: =E6/O6 -> 1.00841e+19 | R6: =Q6*P6 -> 1.4096393e+26 | S6: =R6*N6 -> 0 | X6: 0.01 | Z6: 0.999 | AJ6: =S6*X6*(1-Z6) -> 0 | BF6: estable
B7: Kr-84 | C7: 36084 | E7: 2.38999e-05 | G7: Estable | H7: Estable | M7: =IF(ISNUMBER(BG7),BG7,"") | N7: =IF(ISNUMBER(M7),LN(2)/M7,0) -> 0 | O7: =10^-24 -> 1e-24 | P7: =PI()*$K$97^2*$K$98 -> 13978831 | Q7: =E7/O7 -> 2.38999e+19 | R7: =Q7*P7 -> 3.3409266e+26 | S7: =R7*N7 -> 0 | X7: 0.01 | Z7: 0.999 | AJ7: =S7*X7*(1-Z7) -> 0 | BF7: estable
B8: Kr-86 | C8: 36086 | E8: 4.04672e-05 | G8: 10.76 años | H8: Estable | M8: =IF(ISNUMBER(BG8),BG8,"") | N8: =IF(ISNUMBER(M8),LN(2)/M8,0) -> 0 | O8: =10^-24 -> 1e-24 | P8: =PI()*$K$97^2*$K$98 -> 13978831 | Q8: =E8/O8 -> 4.04672e+19 | R8: =Q8*P8 -> 5.6568414e+26 | S8: =R8*N8 -> 0 | X8: 0.01 | Z8: 0.999 | AJ8: =S8*X8*(1-Z8) -> 0 | BF8: estable
B9: Rb-85 | C9: 37085 | E9: 2.31987e-05 | G9: Estable | H9: Estable | M9: =IF(ISNUMBER(BG9),BG9,"") | N9: =IF(ISNUMBER(M9),LN(2)/M9,0) -> 0 | O9: =10^-24 -> 1e-24 | P9: =PI()*$K$97^2*$K$98 -> 13978831 | Q9: =E9/O9 -> 2.31987e+19 | R9: =Q9*P9 -> 3.242907e+26 | S9: =R9*N9 -> 0 | X9: 0.01 | Z9: 0.999 | AJ9: =S9*X9*(1-Z9) -> 0 | BF9: estable
B10: Pd-107 | C10: 46107 | D10: Ag, Pd | E10: 2.23939e-05 | G10: 6.5 × 10^6 años | H10: 6.5 × 10⁶ años | I10: 6500000 | M10: =IF(ISNUMBER(BG10),BG10,"") -> 205120019520000 | N10: =IF(ISNUMBER(M10),LN(2)/M10,0) -> 3.3792274e-15 | O10: =10^-24 -> 1e-24 | P10: =PI()*$K$97^2*$K$98 -> 13978831 | Q10: =E10/O10 -> 2.23939e+19 | R10: =Q10*P10 -> 3.1304054e+26 | S10: =R10*N10 -> 1.0578351e+12 | T10: =S10*0.000000000027 -> 28.561549 | U10: =D10 -> Ag, Pd | V10: 3e-05 | W10: 8e-05 | X10: 1 | Y10: 1 | Z10: 1 | AA10: 1 | AB10: 500 | AC10: 100 | AD10: 1 | AE10: 1 | AF10: 100 | AG10: 100 | AH10: 10 | AI10: 2 | AJ10: =$S10*(1/X10)*(1/Z10)*(1/AB10)*(1/AD10)*(1/AF10)*(1/AH10) -> 2115670.3 | AK10: =$S10*(1/Y10)*(1/AA10)*(1/AC10)*(1/AE10)*(1/AG10)*(1/AI10) -> 52891757 | AL10: =AK10*0.000000000027 -> 0.0014280774 | AM10: =B10 -> Pd-107 | AO10: =$S10 -> 1.0578351e+12 | AP10: =$S10*(1/X10) -> 1.0578351e+12 | AQ10: =$S10*(1/X10)*(1/Z10) -> 1.0578351e+12 | AR10: =$S10*(1/X10)*(1/Z10)*(1/AB10) -> 2.1156703e+09 | AS10: =$S10*(1/X10)*(1/Z10)*(1/AB10)*(1/AD10) -> 2.1156703e+09 | AT10: =$S10*(1/X10)*(1/Z10)*(1/AB10)*(1/AD10)*(1/AF10) -> 21156703 | AU10: =$S10*(1/X10)*(1/Z10)*(1/AB10)*(1/AD10)*(1/AF10)*(1/AH10) -> 2115670.3 | AX10: =AO10 -> 1.0578351e+12 | AY10: =AX10*(1/Y10) -> 1.0578351e+12 | AZ10: =AY10*(1/AA10) -> 1.0578351e+12 | BA10: =AZ10*(1/AC10) -> 1.0578351e+10 | BB10: =BA10*(1/AE10) -> 1.0578351e+10 | BC10: =BB10*(1/AG10) -> 1.0578351e+08 | BD10: =BC10*(1/AI10) -> 52891757 | BF10: 6.5 My | BG10: 205120019520000
B11: Sr-88 | C11: 38088 | E11: 7.66113e-05 | G11: 2.9 horas | H11: Estable | M11: =IF(ISNUMBER(BG11),BG11,"") | N11: =IF(ISNUMBER(M11),LN(2)/M11,0) -> 0 | O11: =10^-24 -> 1e-24 | P11: =PI()*$K$97^2*$K$98 -> 13978831 | Q11: =E11/O11 -> 7.66113e+19 | R11: =Q11*P11 -> 1.0709364e+27 | S11: =R11*N11 -> 0 | X11: 0.01 | Z11: 0.999 | AJ11: =S11*X11*(1-Z11) -> 0 | BF11: estable
B12: Rb-87 | C12: 37087 | D12: Cs, Rb | E12: 5.62988e-05 | F12: 49.650 E9 a | G12: 4.88 × 10^10 años | H12: 1.6 × 10⁹ años | I12: 1600000000 | M12: =IF(ISNUMBER(BG12),BG12,"") -> 1.5683792e+18 | N12: =IF(ISNUMBER(M12),LN(2)/M12,0) -> 4.4195126e-19 | O12: =10^-24 -> 1e-24 | P12: =PI()*$K$97^2*$K$98 -> 13978831 | Q12: =E12/O12 -> 5.62988e+19 | R12: =Q12*P12 -> 7.8699139e+26 | S12: =R12*N12 -> 3.4781184e+08 | T12: =S12*0.000000000027 -> 0.0093909197 | U12: =D12 -> Cs, Rb | V12: 3e-05 | W12: 8e-05 | X12: 1 | Y12: 1 | Z12: 1 | AA12: 1 | AB12: =10^7 -> 10000000 | AC12: =2000000 -> 2000000 | AD12: 10 | AE12: 3 | AF12: 100 | AG12: 100 | AH12: 10 | AI12: 2 | AJ12: =$S12*(1/X12)*(1/Z12)*(1/AB12)*(1/AD12)*(1/AF12)*(1/AH12) -> 0.0034781184 | AK12: =$S12*(1/Y12)*(1/AA12)*(1/AC12)*(1/AE12)*(1/AG12)*(1/AI12) -> 0.2898432 | AL12: =AK12*0.000000000027 -> 7.8257664e-12 | AM12: =B12 -> Rb-87 | AO12: =$S12 -> 3.4781184e+08 | AP12: =$S12*(1/X12) -> 3.4781184e+08 | AQ12: =$S12*(1/X12)*(1/Z12) -> 3.4781184e+08 | AR12: =$S12*(1/X12)*(1/Z12)*(1/AB12) -> 34.781184 | AS12: =$S12*(1/X12)*(1/Z12)*(1/AB12)*(1/AD12) -> 3.4781184 | AT12: =$S12*(1/X12)*(1/Z12)*(1/AB12)*(1/AD12)*(1/AF12) -> 0.034781184 | AU12: =$S12*(1/X12)*(1/Z12)*(1/AB12)*(1/AD12)*(1/AF12)*(1/AH12) -> 0.0034781184 | AX12: =AO12 -> 3.4781184e+08 | AY12: =AX12*(1/Y12) -> 3.4781184e+08 | AZ12: =AY12*(1/AA12) -> 3.4781184e+08 | BA12: =AZ12*(1/AC12) -> 173.90592 | BB12: =BA12*(1/AE12) -> 57.96864 | BC12: =BB12*(1/AG12) -> 0.5796864 | BD12: =BC12*(1/AI12) -> 0.2898432 | BF12: 49.7 Gy | BG12: 1.5683792e+18
B13: Cs-135 | C13: 55135 | D13: Cs, Rb | E13: 2.74688e-05 | F13: 2.3 E6 a | G13: 2.3 × 10^6 años | H13: 2.3 × 10⁶ años | I13: 2300000 | M13: =IF(ISNUMBER(BG13),BG13,"") -> 41970711686400 | N13: =IF(ISNUMBER(M13),LN(2)/M13,0) -> 1.6515021e-14 | O13: =10^-24 -> 1e-24 | P13: =PI()*$K$97^2*$K$98 -> 13978831 | Q13: =E13/O13 -> 2.74688e+19 | R13: =Q13*P13 -> 3.839817e+26 | S13: =R13*N13 -> 6.3414659e+12 | T13: =S13*0.000000000027 -> 171.21958 | U13: =D13 -> Cs, Rb | V13: 3e-05 | W13: 8e-05 | X13: 1 | Y13: 1 | Z13: 1 | AA13: 1 | AB13: =10^7 -> 10000000 | AC13: =2000000 -> 2000000 | AD13: 10 | AE13: 3 | AF13: 100 | AG13: 100 | AH13: 10 | AI13: 2 | AJ13: =$S13*(1/X13)*(1/Z13)*(1/AB13)*(1/AD13)*(1/AF13)*(1/AH13) -> 63.414659 | AK13: =$S13*(1/Y13)*(1/AA13)*(1/AC13)*(1/AE13)*(1/AG13)*(1/AI13) -> 5284.5549 | AL13: =AK13*0.000000000027 -> 1.4268298e-07 | AM13: =B13 -> Cs-135 | AO13: =$S13 -> 6.3414659e+12 | AP13: =$S13*(1/X13) -> 6.3414659e+12 | AQ13: =$S13*(1/X13)*(1/Z13) -> 6.3414659e+12 | AR13: =$S13*(1/X13)*(1/Z13)*(1/AB13) -> 634146.59 | AS13: =$S13*(1/X13)*(1/Z13)*(1/AB13)*(1/AD13) -> 63414.659 | AT13: =$S13*(1/X13)*(1/Z13)*(1/AB13)*(1/AD13)*(1/AF13) -> 634.14659 | AU13: =$S13*(1/X13)*(1/Z13)*(1/AB13)*(1/AD13)*(1/AF13)*(1/AH13) -> 63.414659 | AX13: =AO13 -> 6.3414659e+12 | AY13: =AX13*(1/Y13) -> 6.3414659e+12 | AZ13: =AY13*(1/AA13) -> 6.3414659e+12 | BA13: =AZ13*(1/AC13) -> 3170732.9 | BB13: =BA13*(1/AE13) -> 1056911 | BC13: =BB13*(1/AG13) -> 10569.11 | BD13: =BC13*(1/AI13) -> 5284.5549 | BF13: 1.33 My | BG13: 41970711686400
B14: Y-89 | C14: 39089 | E14: 7.85848e-05 | G14: Estable | H14: Estable | M14: =IF(ISNUMBER(BG14),BG14,"") | N14: =IF(ISNUMBER(M14),LN(2)/M14,0) -> 0 | O14: =10^-24 -> 1e-24 | P14: =PI()*$K$97^2*$K$98 -> 13978831 | Q14: =E14/O14 -> 7.85848e+19 | R14: =Q14*P14 -> 1.0985236e+27 | S14: =R14*N14 -> 0 | X14: 0.01 | Z14: 0.999 | AJ14: =S14*X14*(1-Z14) -> 0 | BF14: estable
B15: Cs-137 | C15: 55137 | D15: Cs, Rb | E15: 0.000156865 | F15: 30.018 a | G15: 30.17 años | H15: 30.17 años | I15: 30.17 | M15: =IF(ISNUMBER(BG15),BG15,"") -> 9.4797006e+08 | N15: =IF(ISNUMBER(M15),LN(2)/M15,0) -> 7.3119101e-10 | O15: =10^-24 -> 1e-24 | P15: =PI()*$K$97^2*$K$98 -> 13978831 | Q15: =E15/O15 -> 1.56865e+20 | R15: =Q15*P15 -> 2.1927893e+27 | S15: =R15*N15 -> 1.6033478e+18 | T15: =S15*0.000000000027 -> 43290390 | U15: =D15 -> Cs, Rb | V15: 3e-05 | W15: 8e-05 | X15: 1 | Y15: 1 | Z15: 1 | AA15: 1 | AB15: =10^7 -> 10000000 | AC15: =2000000 -> 2000000 | AD15: 10 | AE15: 3 | AF15: 100 | AG15: 100 | AH15: 10 | AI15: 2 | AJ15: =$S15*(1/X15)*(1/Z15)*(1/AB15)*(1/AD15)*(1/AF15)*(1/AH15) -> 16033478 | AK15: =$S15*(1/Y15)*(1/AA15)*(1/AC15)*(1/AE15)*(1/AG15)*(1/AI15) -> 1.3361232e+09 | AL15: =AK15*0.000000000027 -> 0.036075325 | AM15: =B15 -> Cs-137 | AO15: =$S15 -> 1.6033478e+18 | AP15: =$S15*(1/X15) -> 1.6033478e+18 | AQ15: =$S15*(1/X15)*(1/Z15) -> 1.6033478e+18 | AR15: =$S15*(1/X15)*(1/Z15)*(1/AB15) -> 1.6033478e+11 | AS15: =$S15*(1/X15)*(1/Z15)*(1/AB15)*(1/AD15) -> 1.6033478e+10 | AT15: =$S15*(1/X15)*(1/Z15)*(1/AB15)*(1/AD15)*(1/AF15) -> 1.6033478e+08 | AU15: =$S15*(1/X15)*(1/Z15)*(1/AB15)*(1/AD15)*(1/AF15)*(1/AH15) -> 16033478 | AX15: =AO15 -> 1.6033478e+18 | AY15: =AX15*(1/Y15) -> 1.6033478e+18 | AZ15: =AY15*(1/AA15) -> 1.6033478e+18 | BA15: =AZ15*(1/AC15) -> 8.016739e+11 | BB15: =BA15*(1/AE15) -> 2.6722463e+11 | BC15: =BB15*(1/AG15) -> 2.6722463e+09 | BD15: =BC15*(1/AI15) -> 1.3361232e+09 | BF15: 30.04 y | BG15: 9.4797006e+08
B16: Zr-91 | C16: 40091 | E16: 9.39238e-05 | G16: Estable | H16: Estable | M16: =IF(ISNUMBER(BG16),BG16,"") | N16: =IF(ISNUMBER(M16),LN(2)/M16,0) -> 0 | O16: =10^-24 -> 1e-24 | P16: =PI()*$K$97^2*$K$98 -> 13978831 | Q16: =E16/O16 -> 9.39238e+19 | R16: =Q16*P16 -> 1.3129449e+27 | S16: =R16*N16 -> 0 | X16: 0.01 | Z16: 0.999 | AJ16: =S16*X16*(1-Z16) -> 0 | BF16: estable
B17: Zr-92 | C17: 40092 | E17: 0.000134476 | G17: Estable | H17: Estable | M17: =IF(ISNUMBER(BG17),BG17,"") | N17: =IF(ISNUMBER(M17),LN(2)/M17,0) -> 0 | O17: =10^-24 -> 1e-24 | P17: =PI()*$K$97^2*$K$98 -> 13978831 | Q17: =E17/O17 -> 1.34476e+20 | R17: =Q17*P17 -> 1.8798172e+27 | S17: =R17*N17 -> 0 | X17: 0.01 | Z17: 0.999 | AJ17: =S17*X17*(1-Z17) -> 0 | BF17: estable
B18: Xe-133 | C18: 54133 | D18: Gases nobles | E18: 5.19994e-06 | F18: 5.2441 d | G18: 5.243 días | H18: 5.25 días | J18: 5.25 | M18: =IF(ISNUMBER(BG18),BG18,"") -> 453375.36 | N18: =IF(ISNUMBER(M18),LN(2)/M18,0) -> 1.5288594e-06 | O18: =10^-24 -> 1e-24 | P18: =PI()*$K$97^2*$K$98 -> 13978831 | Q18: =E18/O18 -> 5.19994e+18 | R18: =Q18*P18 -> 7.2689081e+25 | S18: =R18*N18 -> 1.1113138e+20 | T18: =S18*0.000000000027 -> 3.0005474e+09 | U18: =D18 -> Gases nobles | V18: 3e-05 | W18: 8e-05 | X18: 2 | Y18: 1 | Z18: 10 | AA18: 5 | AB18: 10000000 | AC18: 2000000 | AD18: 1 | AE18: 1 | AF18: 100 | AG18: 100 | AH18: 1 | AI18: 1 | AJ18: =$S18*(1/X18)*(1/Z18)*(1/AB18)*(1/AD18)*(1/AF18)*(1/AH18) -> 5.5565692e+09 | AK18: =$S18*(1/Y18)*(1/AA18)*(1/AC18)*(1/AE18)*(1/AG18)*(1/AI18) -> 1.1113138e+11 | AL18: =AK18*0.000000000027 -> 3.0005474 | AM18: =B18 -> Xe-133 | AO18: =$S18 -> 1.1113138e+20 | AP18: =$S18*(1/X18) -> 5.5565692e+19 | AQ18: =$S18*(1/X18)*(1/Z18) -> 5.5565692e+18 | AR18: =$S18*(1/X18)*(1/Z18)*(1/AB18) -> 5.5565692e+11 | AS18: =$S18*(1/X18)*(1/Z18)*(1/AB18)*(1/AD18) -> 5.5565692e+11 | AT18: =$S18*(1/X18)*(1/Z18)*(1/AB18)*(1/AD18)*(1/AF18) -> 5.5565692e+09 | AU18: =$S18*(1/X18)*(1/Z18)*(1/AB18)*(1/AD18)*(1/AF18)*(1/AH18) -> 5.5565692e+09 | AX18: =AO18 -> 1.1113138e+20 | AY18: =AX18*(1/Y18) -> 1.1113138e+20 | AZ18: =AY18*(1/AA18) -> 2.2226277e+19 | BA18: =AZ18*(1/AC18) -> 1.1113138e+13 | BB18: =BA18*(1/AE18) -> 1.1113138e+13 | BC18: =BB18*(1/AG18) -> 1.1113138e+11 | BD18: =BC18*(1/AI18) -> 1.1113138e+11 | BF18: 5.2474 d | BG18: 453375.36
B19: Zr-94 | C19: 40094 | E19: 0.000151425 | G19: Estable | H19: Estable | M19: =IF(ISNUMBER(BG19),BG19,"") | N19: =IF(ISNUMBER(M19),LN(2)/M19,0) -> 0 | O19: =10^-24 -> 1e-24 | P19: =PI()*$K$97^2*$K$98 -> 13978831 | Q19: =E19/O19 -> 1.51425e+20 | R19: =Q19*P19 -> 2.1167444e+27 | S19: =R19*N19 -> 0 | X19: 0.01 | Z19: 0.999 | AJ19: =S19*X19*(1-Z19) -> 0 | BF19: estable
B20: Xe-135 | C20: 54135 | D20: Gases nobles | E20: 5.29262e-08 | F20: 9.14 h | G20: 9.14 horas | H20: 9.14 horas | K20: 9.14 | M20: =IF(ISNUMBER(BG20),BG20,"") -> 32904 | N20: =IF(ISNUMBER(M20),LN(2)/M20,0) -> 2.1065742e-05 | O20: =10^-24 -> 1e-24 | P20: =PI()*$K$97^2*$K$98 -> 13978831 | Q20: =E20/O20 -> 5.29262e+16 | R20: =Q20*P20 -> 7.3984639e+23 | S20: =R20*N20 -> 1.5585413e+19 | T20: =S20*0.000000000027 -> 4.2080616e+08 | U20: =D20 -> Gases nobles | V20: 3e-05 | W20: 8e-05 | X20: 2 | Y20: 1 | Z20: 10 | AA20: 5 | AB20: 10000000 | AC20: 2000000 | AD20: 1 | AE20: 1 | AF20: 100 | AG20: 100 | AH20: 1 | AI20: 1 | AJ20: =$S20*(1/X20)*(1/Z20)*(1/AB20)*(1/AD20)*(1/AF20)*(1/AH20) -> 7.7927066e+08 | AK20: =$S20*(1/Y20)*(1/AA20)*(1/AC20)*(1/AE20)*(1/AG20)*(1/AI20) -> 1.5585413e+10 | AL20: =AK20*0.000000000027 -> 0.42080616 | AM20: =B20 -> Xe-135 | AO20: =$S20 -> 1.5585413e+19 | AP20: =$S20*(1/X20) -> 7.7927066e+18 | AQ20: =$S20*(1/X20)*(1/Z20) -> 7.7927066e+17 | AR20: =$S20*(1/X20)*(1/Z20)*(1/AB20) -> 7.7927066e+10 | AS20: =$S20*(1/X20)*(1/Z20)*(1/AB20)*(1/AD20) -> 7.7927066e+10 | AT20: =$S20*(1/X20)*(1/Z20)*(1/AB20)*(1/AD20)*(1/AF20) -> 7.7927066e+08 | AU20: =$S20*(1/X20)*(1/Z20)*(1/AB20)*(1/AD20)*(1/AF20)*(1/AH20) -> 7.7927066e+08 | AX20: =AO20 -> 1.5585413e+19 | AY20: =AX20*(1/Y20) -> 1.5585413e+19 | AZ20: =AY20*(1/AA20) -> 3.1170827e+18 | BA20: =AZ20*(1/AC20) -> 1.5585413e+12 | BB20: =BA20*(1/AE20) -> 1.5585413e+12 | BC20: =BB20*(1/AG20) -> 1.5585413e+10 | BD20: =BC20*(1/AI20) -> 1.5585413e+10 | BF20: 9.14 h | BG20: 32904
B21: Zr-96 | C21: 40096 | E21: 0.000151236 | G21: Estable | H21: Estable | M21: =IF(ISNUMBER(BG21),BG21,"") | N21: =IF(ISNUMBER(M21),LN(2)/M21,0) -> 0 | O21: =10^-24 -> 1e-24 | P21: =PI()*$K$97^2*$K$98 -> 13978831 | Q21: =E21/O21 -> 1.51236e+20 | R21: =Q21*P21 -> 2.1141024e+27 | S21: =R21*N21 -> 0 | X21: 0.01 | Z21: 0.999 | AJ21: =S21*X21*(1-Z21) -> 0 | BF21: 23.4 Ey (estable a efectos prácticos)
B22: I-129 | C22: 53129 | D22: I, Br, Se, Te | E22: 1.74196e-05 | F22: 16.1 E6 a | G22: 1.57 × 10^7 años | H22: 1.57 × 10⁷ años | I22: 15700000 | M22: =IF(ISNUMBER(BG22),BG22,"") -> 509328786931200 | N22: =IF(ISNUMBER(M22),LN(2)/M22,0) -> 1.3609032e-15 | O22: =10^-24 -> 1e-24 | P22: =PI()*$K$97^2*$K$98 -> 13978831 | Q22: =E22/O22 -> 1.74196e+19 | R22: =Q22*P22 -> 2.4350564e+26 | S22: =R22*N22 -> 3.3138761e+11 | T22: =S22*0.000000000027 -> 8.9474653 | U22: =D22 -> I, Br, Se, Te | V22: 3e-05 | W22: 8e-05 | X22: 2 | Y22: 1 | Z22: 10 | AA22: 5 | AB22: =10^7 -> 10000000 | AC22: =2000000 -> 2000000 | AD22: 1 | AE22: 1 | AF22: 100 | AG22: 100 | AH22: 10 | AI22: 2 | AJ22: =$S22*(1/X22)*(1/Z22)*(1/AB22)*(1/AD22)*(1/AF22)*(1/AH22) -> 1.656938 | AK22: =$S22*(1/Y22)*(1/AA22)*(1/AC22)*(1/AE22)*(1/AG22)*(1/AI22) -> 165.6938 | AL22: =AK22*0.000000000027 -> 4.4737327e-09 | AM22: =B22 -> I-129 | AO22: =$S22 -> 3.3138761e+11 | AP22: =$S22*(1/X22) -> 1.656938e+11 | AQ22: =$S22*(1/X22)*(1/Z22) -> 1.656938e+10 | AR22: =$S22*(1/X22)*(1/Z22)*(1/AB22) -> 1656.938 | AS22: =$S22*(1/X22)*(1/Z22)*(1/AB22)*(1/AD22) -> 1656.938 | AT22: =$S22*(1/X22)*(1/Z22)*(1/AB22)*(1/AD22)*(1/AF22) -> 16.56938 | AU22: =$S22*(1/X22)*(1/Z22)*(1/AB22)*(1/AD22)*(1/AF22)*(1/AH22) -> 1.656938 | AX22: =AO22 -> 3.3138761e+11 | AY22: =AX22*(1/Y22) -> 3.3138761e+11 | AZ22: =AY22*(1/AA22) -> 6.6277521e+10 | BA22: =AZ22*(1/AC22) -> 33138.761 | BB22: =BA22*(1/AE22) -> 33138.761 | BC22: =BB22*(1/AG22) -> 331.38761 | BD22: =BC22*(1/AI22) -> 165.6938 | BF22: 16.14 My | BG22: 509328786931200
B23: Mo-95 | C23: 42095 | E23: 8.55988e-05 | G23: Estable | H23: Estable | M23: =IF(ISNUMBER(BG23),BG23,"") | N23: =IF(ISNUMBER(M23),LN(2)/M23,0) -> 0 | O23: =10^-24 -> 1e-24 | P23: =PI()*$K$97^2*$K$98 -> 13978831 | Q23: =E23/O23 -> 8.55988e+19 | R23: =Q23*P23 -> 1.1965711e+27 | S23: =R23*N23 -> 0 | X23: 0.01 | Z23: 0.999 | AJ23: =S23*X23*(1-Z23) -> 0 | BF23: estable
B24: Mo-97 | C24: 42097 | E24: 0.000108613 | G24: Estable | H24: Estable | M24: =IF(ISNUMBER(BG24),BG24,"") | N24: =IF(ISNUMBER(M24),LN(2)/M24,0) -> 0 | O24: =10^-24 -> 1e-24 | P24: =PI()*$K$97^2*$K$98 -> 13978831 | Q24: =E24/O24 -> 1.08613e+20 | R24: =Q24*P24 -> 1.5182827e+27 | S24: =R24*N24 -> 0 | X24: 0.01 | Z24: 0.999 | AJ24: =S24*X24*(1-Z24) -> 0 | BF24: estable
B25: Mo-98 | C25: 42098 | E25: 0.000145386 | G25: Estable | H25: Estable | M25: =IF(ISNUMBER(BG25),BG25,"") | N25: =IF(ISNUMBER(M25),LN(2)/M25,0) -> 0 | O25: =10^-24 -> 1e-24 | P25: =PI()*$K$97^2*$K$98 -> 13978831 | Q25: =E25/O25 -> 1.45386e+20 | R25: =Q25*P25 -> 2.0323263e+27 | S25: =R25*N25 -> 0 | X25: 0.01 | Z25: 0.999 | AJ25: =S25*X25*(1-Z25) -> 0 | BF25: estable
B26: Mo-100 | C26: 42100 | E26: 0.000160969 | G26: Estable | H26: Estable | M26: =IF(ISNUMBER(BG26),BG26,"") | N26: =IF(ISNUMBER(M26),LN(2)/M26,0) -> 0 | O26: =10^-24 -> 1e-24 | P26: =PI()*$K$97^2*$K$98 -> 13978831 | Q26: =E26/O26 -> 1.60969e+20 | R26: =Q26*P26 -> 2.2501584e+27 | S26: =R26*N26 -> 0 | X26: 0.01 | Z26: 0.999 | AJ26: =S26*X26*(1-Z26) -> 0 | BF26: 7.07 Ey (estable a efectos prácticos)
B27: Tc-99 | C27: 43099 | D27: Mo, Ru, Rh, Tc | E27: 0.000135738 | F27: 211.5 E3 a | G27: 2.11 × 10^5 años | H27: 2.13 × 10⁵ años | I27: 213000 | M27: =IF(ISNUMBER(BG27),BG27,"") -> 6661667095488 | N27: =IF(ISNUMBER(M27),LN(2)/M27,0) -> 1.0405011e-13 | O27: =10^-24 -> 1e-24 | P27: =PI()*$K$97^2*$K$98 -> 13978831 | Q27: =E27/O27 -> 1.35738e+20 | R27: =Q27*P27 -> 1.8974585e+27 | S27: =R27*N27 -> 197430763636864 | T27: =S27*0.000000000027 -> 5330.6306 | U27: =D27 -> Mo, Ru, Rh, Tc | V27: 3e-05 | W27: 8e-05 | X27: 1 | Y27: 1 | Z27: 100 | AA27: 50 | AB27: =10^7 -> 10000000 | AC27: =2000000 -> 2000000 | AD27: 10 | AE27: 3 | AF27: 100 | AG27: 100 | AH27: 10 | AI27: 2 | AJ27: =$S27*(1/X27)*(1/Z27)*(1/AB27)*(1/AD27)*(1/AF27)*(1/AH27) -> 19.743076 | AK27: =$S27*(1/Y27)*(1/AA27)*(1/AC27)*(1/AE27)*(1/AG27)*(1/AI27) -> 3290.5127 | AL27: =AK27*0.000000000027 -> 8.8843844e-08 | AM27: =B27 -> Tc-99 | AO27: =$S27 -> 197430763636864 | AP27: =$S27*(1/X27) -> 197430763636864 | AQ27: =$S27*(1/X27)*(1/Z27) -> 1.9743076e+12 | AR27: =$S27*(1/X27)*(1/Z27)*(1/AB27) -> 197430.76 | AS27: =$S27*(1/X27)*(1/Z27)*(1/AB27)*(1/AD27) -> 19743.076 | AT27: =$S27*(1/X27)*(1/Z27)*(1/AB27)*(1/AD27)*(1/AF27) -> 197.43076 | AU27: =$S27*(1/X27)*(1/Z27)*(1/AB27)*(1/AD27)*(1/AF27)*(1/AH27) -> 19.743076 | AX27: =AO27 -> 197430763636864 | AY27: =AX27*(1/Y27) -> 197430763636864 | AZ27: =AY27*(1/AA27) -> 3.9486153e+12 | BA27: =AZ27*(1/AC27) -> 1974307.6 | BB27: =BA27*(1/AE27) -> 658102.55 | BC27: =BB27*(1/AG27) -> 6581.0255 | BD27: =BC27*(1/AI27) -> 3290.5127 | BF27: 211.1 ky | BG27: 6661667095488
B28: Ru-100 | C28: 44100 | E28: 1.63406e-05 | G28: Estable | H28: Estable | M28: =IF(ISNUMBER(BG28),BG28,"") | N28: =IF(ISNUMBER(M28),LN(2)/M28,0) -> 0 | O28: =10^-24 -> 1e-24 | P28: =PI()*$K$97^2*$K$98 -> 13978831 | Q28: =E28/O28 -> 1.63406e+19 | R28: =Q28*P28 -> 2.2842248e+26 | S28: =R28*N28 -> 0 | X28: 0.01 | Z28: 0.999 | AJ28: =S28*X28*(1-Z28) -> 0 | BF28: estable
B29: Ru-101 | C29: 44101 | E29: 0.000130448 | G29: Estable | H29: Estable | M29: =IF(ISNUMBER(BG29),BG29,"") | N29: =IF(ISNUMBER(M29),LN(2)/M29,0) -> 0 | O29: =10^-24 -> 1e-24 | P29: =PI()*$K$97^2*$K$98 -> 13978831 | Q29: =E29/O29 -> 1.30448e+20 | R29: =Q29*P29 -> 1.8235105e+27 | S29: =R29*N29 -> 0 | X29: 0.01 | Z29: 0.999 | AJ29: =S29*X29*(1-Z29) -> 0 | BF29: estable
B30: Ru-102 | C30: 44102 | E30: 0.000124524 | G30: Estable | H30: Estable | M30: =IF(ISNUMBER(BG30),BG30,"") | N30: =IF(ISNUMBER(M30),LN(2)/M30,0) -> 0 | O30: =10^-24 -> 1e-24 | P30: =PI()*$K$97^2*$K$98 -> 13978831 | Q30: =E30/O30 -> 1.24524e+20 | R30: =Q30*P30 -> 1.7406999e+27 | S30: =R30*N30 -> 0 | X30: 0.01 | Z30: 0.999 | AJ30: =S30*X30*(1-Z30) -> 0 | BF30: estable
B31: Ru-103 | C31: 44103 | D31: Mo, Ru, Rh, Tc | E31: 2.04804e-05 | F31: 39.255 d | G31: 39.26 días | H31: 39.26 días | J31: 39.62 | M31: =IF(ISNUMBER(BG31),BG31,"") -> 3390768 | N31: =IF(ISNUMBER(M31),LN(2)/M31,0) -> 2.0442188e-07 | O31: =10^-24 -> 1e-24 | P31: =PI()*$K$97^2*$K$98 -> 13978831 | Q31: =E31/O31 -> 2.04804e+19 | R31: =Q31*P31 -> 2.8629204e+26 | S31: =R31*N31 -> 5.8524359e+19 | T31: =S31*0.000000000027 -> 1.5801577e+09 | U31: =D31 -> Mo, Ru, Rh, Tc | V31: 3e-05 | W31: 8e-05 | X31: 1 | Y31: 1 | Z31: 100 | AA31: 50 | AB31: =10^7 -> 10000000 | AC31: =2000000 -> 2000000 | AD31: 10 | AE31: 3 | AF31: 100 | AG31: 100 | AH31: 10 | AI31: 2 | AJ31: =$S31*(1/X31)*(1/Z31)*(1/AB31)*(1/AD31)*(1/AF31)*(1/AH31) -> 5852435.9 | AK31: =$S31*(1/Y31)*(1/AA31)*(1/AC31)*(1/AE31)*(1/AG31)*(1/AI31) -> 9.7540598e+08 | AL31: =AK31*0.000000000027 -> 0.026335961 | AM31: =B31 -> Ru-103 | AO31: =$S31 -> 5.8524359e+19 | AP31: =$S31*(1/X31) -> 5.8524359e+19 | AQ31: =$S31*(1/X31)*(1/Z31) -> 5.8524359e+17 | AR31: =$S31*(1/X31)*(1/Z31)*(1/AB31) -> 5.8524359e+10 | AS31: =$S31*(1/X31)*(1/Z31)*(1/AB31)*(1/AD31) -> 5.8524359e+09 | AT31: =$S31*(1/X31)*(1/Z31)*(1/AB31)*(1/AD31)*(1/AF31) -> 58524359 | AU31: =$S31*(1/X31)*(1/Z31)*(1/AB31)*(1/AD31)*(1/AF31)*(1/AH31) -> 5852435.9 | AX31: =AO31 -> 5.8524359e+19 | AY31: =AX31*(1/Y31) -> 5.8524359e+19 | AZ31: =AY31*(1/AA31) -> 1.1704872e+18 | BA31: =AZ31*(1/AC31) -> 5.8524359e+11 | BB31: =BA31*(1/AE31) -> 1.950812e+11 | BC31: =BB31*(1/AG31) -> 1.950812e+09 | BD31: =BC31*(1/AI31) -> 9.7540598e+08 | BF31: 39.245 d | BG31: 3390768
B32: Ru-104 | C32: 44104 | E32: 7.27908e-05 | G32: Estable | H32: Estable | M32: =IF(ISNUMBER(BG32),BG32,"") | N32: =IF(ISNUMBER(M32),LN(2)/M32,0) -> 0 | O32: =10^-24 -> 1e-24 | P32: =PI()*$K$97^2*$K$98 -> 13978831 | Q32: =E32/O32 -> 7.27908e+19 | R32: =Q32*P32 -> 1.0175303e+27 | S32: =R32*N32 -> 0 | X32: 0.01 | Z32: 0.999 | AJ32: =S32*X32*(1-Z32) -> 0 | BF32: estable
B33: Ru-106 | C33: 44106 | D33: Mo, Ru, Rh, Tc | E33: 2.6273e-05 | F33: 371.5 d | G33: 373.59 días | H33: 373.6 días | J33: 373.6 | M33: =IF(ISNUMBER(BG33),BG33,"") -> 32123520 | N33: =IF(ISNUMBER(M33),LN(2)/M33,0) -> 2.157756e-08 | O33: =10^-24 -> 1e-24 | P33: =PI()*$K$97^2*$K$98 -> 13978831 | Q33: =E33/O33 -> 2.6273e+19 | R33: =Q33*P33 -> 3.6726582e+26 | S33: =R33*N33 -> 7.9247002e+18 | T33: =S33*0.000000000027 -> 2.1396691e+08 | U33: =D33 -> Mo, Ru, Rh, Tc | V33: 3e-05 | W33: 8e-05 | X33: 1 | Y33: 1 | Z33: 100 | AA33: 50 | AB33: =10^7 -> 10000000 | AC33: =2000000 -> 2000000 | AD33: 10 | AE33: 3 | AF33: 100 | AG33: 100 | AH33: 10 | AI33: 2 | AJ33: =$S33*(1/X33)*(1/Z33)*(1/AB33)*(1/AD33)*(1/AF33)*(1/AH33) -> 792470.02 | AK33: =$S33*(1/Y33)*(1/AA33)*(1/AC33)*(1/AE33)*(1/AG33)*(1/AI33) -> 1.3207834e+08 | AL33: =AK33*0.000000000027 -> 0.0035661151 | AM33: =B33 -> Ru-106 | AO33: =$S33 -> 7.9247002e+18 | AP33: =$S33*(1/X33) -> 7.9247002e+18 | AQ33: =$S33*(1/X33)*(1/Z33) -> 7.9247002e+16 | AR33: =$S33*(1/X33)*(1/Z33)*(1/AB33) -> 7.9247002e+09 | AS33: =$S33*(1/X33)*(1/Z33)*(1/AB33)*(1/AD33) -> 7.9247002e+08 | AT33: =$S33*(1/X33)*(1/Z33)*(1/AB33)*(1/AD33)*(1/AF33) -> 7924700.2 | AU33: =$S33*(1/X33)*(1/Z33)*(1/AB33)*(1/AD33)*(1/AF33)*(1/AH33) -> 792470.02 | AX33: =AO33 -> 7.9247002e+18 | AY33: =AX33*(1/Y33) -> 7.9247002e+18 | AZ33: =AY33*(1/AA33) -> 1.58494e+17 | BA33: =AZ33*(1/AC33) -> 7.9247002e+10 | BB33: =BA33*(1/AE33) -> 2.6415667e+10 | BC33: =BB33*(1/AG33) -> 2.6415667e+08 | BD33: =BC33*(1/AI33) -> 1.3207834e+08 | BF33: 371.8 d | BG33: 32123520
B34: Rh-103 | C34: 45103 | E34: 5.49655e-05 | G34: Estable | H34: Estable | M34: =IF(ISNUMBER(BG34),BG34,"") | N34: =IF(ISNUMBER(M34),LN(2)/M34,0) -> 0 | O34: =10^-24 -> 1e-24 | P34: =PI()*$K$97^2*$K$98 -> 13978831 | Q34: =E34/O34 -> 5.49655e+19 | R34: =Q34*P34 -> 7.6835342e+26 | S34: =R34*N34 -> 0 | X34: 0.01 | Z34: 0.999 | AJ34: =S34*X34*(1-Z34) -> 0 | BF34: estable
B35: Rh-105 | C35: 45105 | D35: Mo, Ru, Rh, Tc | E35: 4.30968e-07 | G35: 35.36 horas | H35: 35.36 horas | K35: 35.36 | M35: =IF(ISNUMBER(BG35),BG35,"") -> 127227.6 | N35: =IF(ISNUMBER(M35),LN(2)/M35,0) -> 5.4480882e-06 | O35: =10^-24 -> 1e-24 | P35: =PI()*$K$97^2*$K$98 -> 13978831 | Q35: =E35/O35 -> 4.30968e+17 | R35: =Q35*P35 -> 6.0244287e+24 | S35: =R35*N35 -> 3.2821619e+19 | T35: =S35*0.000000000027 -> 8.861837e+08 | U35: =D35 -> Mo, Ru, Rh, Tc | V35: 3e-05 | W35: 8e-05 | X35: 1 | Y35: 1 | Z35: 100 | AA35: 50 | AB35: =10^7 -> 10000000 | AC35: =2000000 -> 2000000 | AD35: 10 | AE35: 3 | AF35: 100 | AG35: 100 | AH35: 10 | AI35: 2 | AJ35: =$S35*(1/X35)*(1/Z35)*(1/AB35)*(1/AD35)*(1/AF35)*(1/AH35) -> 3282161.9 | AK35: =$S35*(1/Y35)*(1/AA35)*(1/AC35)*(1/AE35)*(1/AG35)*(1/AI35) -> 5.4702698e+08 | AL35: =AK35*0.000000000027 -> 0.014769728 | AM35: =B35 -> Rh-105 | AO35: =$S35 -> 3.2821619e+19 | AP35: =$S35*(1/X35) -> 3.2821619e+19 | AQ35: =$S35*(1/X35)*(1/Z35) -> 3.2821619e+17 | AR35: =$S35*(1/X35)*(1/Z35)*(1/AB35) -> 3.2821619e+10 | AS35: =$S35*(1/X35)*(1/Z35)*(1/AB35)*(1/AD35) -> 3.2821619e+09 | AT35: =$S35*(1/X35)*(1/Z35)*(1/AB35)*(1/AD35)*(1/AF35) -> 32821619 | AU35: =$S35*(1/X35)*(1/Z35)*(1/AB35)*(1/AD35)*(1/AF35)*(1/AH35) -> 3282161.9 | AX35: =AO35 -> 3.2821619e+19 | AY35: =AX35*(1/Y35) -> 3.2821619e+19 | AZ35: =AY35*(1/AA35) -> 6.5643237e+17 | BA35: =AZ35*(1/AC35) -> 3.2821619e+11 | BB35: =BA35*(1/AE35) -> 1.094054e+11 | BC35: =BB35*(1/AG35) -> 1.094054e+09 | BD35: =BC35*(1/AI35) -> 5.4702698e+08 | BF35: 35.341 h | BG35: 127227.6
B36: Pd-105 | C36: 46105 | E36: 4.12532e-05 | G36: Estable | H36: Estable | M36: =IF(ISNUMBER(BG36),BG36,"") | N36: =IF(ISNUMBER(M36),LN(2)/M36,0) -> 0 | O36: =10^-24 -> 1e-24 | P36: =PI()*$K$97^2*$K$98 -> 13978831 | Q36: =E36/O36 -> 4.12532e+19 | R36: =Q36*P36 -> 5.766715e+26 | S36: =R36*N36 -> 0 | X36: 0.01 | Z36: 0.999 | AJ36: =S36*X36*(1-Z36) -> 0 | BF36: estable
B37: Pd-106 | C37: 46106 | E37: 1.77633e-05 | G37: Estable | H37: Estable | M37: =IF(ISNUMBER(BG37),BG37,"") | N37: =IF(ISNUMBER(M37),LN(2)/M37,0) -> 0 | O37: =10^-24 -> 1e-24 | P37: =PI()*$K$97^2*$K$98 -> 13978831 | Q37: =E37/O37 -> 1.77633e+19 | R37: =Q37*P37 -> 2.4831016e+26 | S37: =R37*N37 -> 0 | X37: 0.01 | Z37: 0.999 | AJ37: =S37*X37*(1-Z37) -> 0 | BF37: estable
B38: U-235 | C38: 92235 | D38: Pu, Actinidos | E38: 0.00223551 | F38: 704 E6 a | G38: 7.04 × 10^8 años | H38: 703.8E6 (años) | I38: 703800000 | M38: =IF(ISNUMBER(BG38),BG38,"") -> 2.2216076e+16 | N38: =IF(ISNUMBER(M38),LN(2)/M38,0) -> 3.1200253e-17 | O38: =10^-24 -> 1e-24 | P38: =PI()*$K$97^2*$K$98 -> 13978831 | Q38: =E38/O38 -> 2.23551e+21 | R38: =Q38*P38 -> 3.1249816e+28 | S38: =R38*N38 -> 9.7500214e+11 | T38: =S38*0.000000000027 -> 26.325058 | U38: =D38 -> Pu, Actinidos | V38: 3e-05 | W38: 8e-05 | X38: 1 | Y38: 1 | Z38: 200 | AA38: 100 | AB38: =10^7 -> 10000000 | AC38: =2000000 -> 2000000 | AD38: 100 | AE38: 30 | AF38: 100 | AG38: 100 | AH38: 10 | AI38: 2 | AJ38: =$S38*(1/X38)*(1/Z38)*(1/AB38)*(1/AD38)*(1/AF38)*(1/AH38) -> 0.0048750107 | AK38: =$S38*(1/Y38)*(1/AA38)*(1/AC38)*(1/AE38)*(1/AG38)*(1/AI38) -> 0.81250179 | AL38: =AK38*0.000000000027 -> 2.1937548e-11 | AM38: =B38 -> U-235 | AO38: =$S38 -> 9.7500214e+11 | AP38: =$S38*(1/X38) -> 9.7500214e+11 | AQ38: =$S38*(1/X38)*(1/Z38) -> 4.8750107e+09 | AR38: =$S38*(1/X38)*(1/Z38)*(1/AB38) -> 487.50107 | AS38: =$S38*(1/X38)*(1/Z38)*(1/AB38)*(1/AD38) -> 4.8750107 | AT38: =$S38*(1/X38)*(1/Z38)*(1/AB38)*(1/AD38)*(1/AF38) -> 0.048750107 | AU38: =$S38*(1/X38)*(1/Z38)*(1/AB38)*(1/AD38)*(1/AF38)*(1/AH38) -> 0.0048750107 | AX38: =AO38 -> 9.7500214e+11 | AY38: =AX38*(1/Y38) -> 9.7500214e+11 | AZ38: =AY38*(1/AA38) -> 9.7500214e+09 | BA38: =AZ38*(1/AC38) -> 4875.0107 | BB38: =BA38*(1/AE38) -> 162.50036 | BC38: =BB38*(1/AG38) -> 1.6250036 | BD38: =BC38*(1/AI38) -> 0.81250179 | BF38: 704 My | BG38: 2.2216076e+16
B39: Pd-108 | C39: 46108 | E39: 1.4544e-05 | G39: Estable | H39: Estable | M39: =IF(ISNUMBER(BG39),BG39,"") | N39: =IF(ISNUMBER(M39),LN(2)/M39,0) -> 0 | O39: =10^-24 -> 1e-24 | P39: =PI()*$K$97^2*$K$98 -> 13978831 | Q39: =E39/O39 -> 1.4544e+19 | R39: =Q39*P39 -> 2.0330811e+26 | S39: =R39*N39 -> 0 | X39: 0.01 | Z39: 0.999 | AJ39: =S39*X39*(1-Z39) -> 0 | BF39: estable
B40: Ag-109 | C40: 47109 | E40: 7.83917e-06 | G40: Estable | H40: Estable | M40: =IF(ISNUMBER(BG40),BG40,"") | N40: =IF(ISNUMBER(M40),LN(2)/M40,0) -> 0 | O40: =10^-24 -> 1e-24 | P40: =PI()*$K$97^2*$K$98 -> 13978831 | Q40: =E40/O40 -> 7.83917e+18 | R40: =Q40*P40 -> 1.0958243e+26 | S40: =R40*N40 -> 0 | X40: 0.01 | Z40: 0.999 | AJ40: =S40*X40*(1-Z40) -> 0 | BF40: estable
B41: Te-130 | C41: 52130 | E41: 4.8028e-05 | G41: Estable | H41: Estable | M41: =IF(ISNUMBER(BG41),BG41,"") | N41: =IF(ISNUMBER(M41),LN(2)/M41,0) -> 0 | O41: =10^-24 -> 1e-24 | P41: =PI()*$K$97^2*$K$98 -> 13978831 | Q41: =E41/O41 -> 4.8028e+19 | R41: =Q41*P41 -> 6.7137528e+26 | S41: =R41*N41 -> 0 | X41: 0.01 | Z41: 0.999 | AJ41: =S41*X41*(1-Z41) -> 0 | BF41: 791 Ey (estable a efectos prácticos)
...

Sheet Hoja1
D5: Isotopo | E5: AF 95%
E6: Core Activity | F6: HMC | G6: Kernel | H6: Diff | I6: Graphite | J6: FLIBE | K6: Reactor Building
D7: Np-239 | E7: ='AZ6 RZ1 (ACCIDENT)'!AX51 -> 8.1822081e+20 | F7: ='AZ6 RZ1 (ACCIDENT)'!AY51 -> 8.1822081e+20 | G7: ='AZ6 RZ1 (ACCIDENT)'!AZ51 -> 8.1822081e+18 | H7: ='AZ6 RZ1 (ACCIDENT)'!BA51 -> 4.0911041e+12 | I7: ='AZ6 RZ1 (ACCIDENT)'!BB51 -> 1.3637014e+11 | J7: ='AZ6 RZ1 (ACCIDENT)'!BC51 -> 1.3637014e+09 | K7: ='AZ6 RZ1 (ACCIDENT)'!BD51 -> 6.8185068e+08
D8: Xe-133 | E8: ='AZ6 RZ1 (ACCIDENT)'!AX18 -> 1.1113138e+20 | F8: ='AZ6 RZ1 (ACCIDENT)'!AY18 -> 1.1113138e+20 | G8: ='AZ6 RZ1 (ACCIDENT)'!AZ18 -> 2.2226277e+19 | H8: ='AZ6 RZ1 (ACCIDENT)'!BA18 -> 1.1113138e+13 | I8: ='AZ6 RZ1 (ACCIDENT)'!BB18 -> 1.1113138e+13 | J8: ='AZ6 RZ1 (ACCIDENT)'!BC18 -> 1.1113138e+11 | K8: ='AZ6 RZ1 (ACCIDENT)'!BD18 -> 1.1113138e+11
D9: Ba-140 | E9: ='AZ6 RZ1 (ACCIDENT)'!AX63 -> 9.6890023e+19 | F9: ='AZ6 RZ1 (ACCIDENT)'!AY63 -> 9.6890023e+19 | G9: ='AZ6 RZ1 (ACCIDENT)'!AZ63 -> 9.6890023e+19 | H9: ='AZ6 RZ1 (ACCIDENT)'!BA63 -> 484450113422510 | I9: ='AZ6 RZ1 (ACCIDENT)'!BB63 -> 1.6148337e+13 | J9: ='AZ6 RZ1 (ACCIDENT)'!BC63 -> 1.6148337e+11 | K9: ='AZ6 RZ1 (ACCIDENT)'!BD63 -> 8.0741686e+10
D10: Pr-143 | E10: ='AZ6 RZ1 (ACCIDENT)'!AX76 -> 8.8154606e+19 | F10: ='AZ6 RZ1 (ACCIDENT)'!AY76 -> 8.8154606e+19 | G10: ='AZ6 RZ1 (ACCIDENT)'!AZ76 -> 1.7630921e+18 | H10: ='AZ6 RZ1 (ACCIDENT)'!BA76 -> 8.8154606e+11 | I10: ='AZ6 RZ1 (ACCIDENT)'!BB76 -> 2.9384869e+10 | J10: ='AZ6 RZ1 (ACCIDENT)'!BC76 -> 2.9384869e+08 | K10: ='AZ6 RZ1 (ACCIDENT)'!BD76 -> 1.4692434e+08
D11: Ce-141 | E11: ='AZ6 RZ1 (ACCIDENT)'!AX72 -> 8.0593088e+19 | F11: ='AZ6 RZ1 (ACCIDENT)'!AY72 -> 8.0593088e+19 | G11: ='AZ6 RZ1 (ACCIDENT)'!AZ72 -> 1.6118618e+18 | H11: ='AZ6 RZ1 (ACCIDENT)'!BA72 -> 8.0593088e+11 | I11: ='AZ6 RZ1 (ACCIDENT)'!BB72 -> 2.6864363e+10 | J11: ='AZ6 RZ1 (ACCIDENT)'!BC72 -> 2.6864363e+08 | K11: ='AZ6 RZ1 (ACCIDENT)'!BD72 -> 1.3432181e+08
D12: Zr-95 | E12: ='AZ6 RZ1 (ACCIDENT)'!AX69 -> 7.6195384e+19 | F12: ='AZ6 RZ1 (ACCIDENT)'!AY69 -> 7.6195384e+19 | G12: ='AZ6 RZ1 (ACCIDENT)'!AZ69 -> 1.5239077e+18 | H12: ='AZ6 RZ1 (ACCIDENT)'!BA69 -> 7.6195384e+11 | I12: ='AZ6 RZ1 (ACCIDENT)'!BB69 -> 2.5398461e+11 | J12: ='AZ6 RZ1 (ACCIDENT)'!BC69 -> 2.5398461e+09 | K12: ='AZ6 RZ1 (ACCIDENT)'!BD69 -> 1.2699231e+09
D13: Nb-95 | E13: ='AZ6 RZ1 (ACCIDENT)'!AX70 -> 6.4794892e+19 | F13: ='AZ6 RZ1 (ACCIDENT)'!AY70 -> 6.4794892e+19 | G13: ='AZ6 RZ1 (ACCIDENT)'!AZ70 -> 1.2958978e+18 | H13: ='AZ6 RZ1 (ACCIDENT)'!BA70 -> 6.4794892e+11 | I13: ='AZ6 RZ1 (ACCIDENT)'!BB70 -> 2.1598297e+11 | J13: ='AZ6 RZ1 (ACCIDENT)'!BC70 -> 2.1598297e+09 | K13: ='AZ6 RZ1 (ACCIDENT)'!BD70 -> 1.0799149e+09
D14: Y-91 | E14: ='AZ6 RZ1 (ACCIDENT)'!AX66 -> 6.3124929e+19 | F14: ='AZ6 RZ1 (ACCIDENT)'!AY66 -> 6.3124929e+19 | G14: ='AZ6 RZ1 (ACCIDENT)'!AZ66 -> 1.2624986e+18 | H14: ='AZ6 RZ1 (ACCIDENT)'!BA66 -> 6.3124929e+11 | I14: ='AZ6 RZ1 (ACCIDENT)'!BB66 -> 2.1041643e+11 | J14: ='AZ6 RZ1 (ACCIDENT)'!BC66 -> 2.1041643e+09 | K14: ='AZ6 RZ1 (ACCIDENT)'!BD66 -> 1.0520821e+09
D15: Ru-103 | E15: ='AZ6 RZ1 (ACCIDENT)'!AX31 -> 5.8524359e+19 | F15: ='AZ6 RZ1 (ACCIDENT)'!AY31 -> 5.8524359e+19 | G15: ='AZ6 RZ1 (ACCIDENT)'!AZ31 -> 1.1704872e+18 | H15: ='AZ6 RZ1 (ACCIDENT)'!BA31 -> 5.8524359e+11 | I15: ='AZ6 RZ1 (ACCIDENT)'!BB31 -> 1.950812e+11 | J15: ='AZ6 RZ1 (ACCIDENT)'!BC31 -> 1.950812e+09 | K15: ='AZ6 RZ1 (ACCIDENT)'!BD31 -> 9.7540598e+08
D16: Sr-89 | E16: ='AZ6 RZ1 (ACCIDENT)'!AX60 -> 5.1756066e+19 | F16: ='AZ6 RZ1 (ACCIDENT)'!AY60 -> 5.1756066e+19 | G16: ='AZ6 RZ1 (ACCIDENT)'!AZ60 -> 5.1756066e+19 | H16: ='AZ6 RZ1 (ACCIDENT)'!BA60 -> 258780329205576 | I16: ='AZ6 RZ1 (ACCIDENT)'!BB60 -> 8.626011e+12 | J16: ='AZ6 RZ1 (ACCIDENT)'!BC60 -> 8.626011e+10 | K16: ='AZ6 RZ1 (ACCIDENT)'!BD60 -> 4.3130055e+10
D17: U-237 | E17: ='AZ6 RZ1 (ACCIDENT)'!AX42 -> 4.7277744e+19 | F17: ='AZ6 RZ1 (ACCIDENT)'!AY42 -> 4.7277744e+19 | G17: ='AZ6 RZ1 (ACCIDENT)'!AZ42 -> 4.7277744e+17 | H17: ='AZ6 RZ1 (ACCIDENT)'!BA42 -> 2.3638872e+11 | I17: ='AZ6 RZ1 (ACCIDENT)'!BB42 -> 7.8796239e+09 | J17: ='AZ6 RZ1 (ACCIDENT)'!BC42 -> 78796239 | K17: ='AZ6 RZ1 (ACCIDENT)'!BD42 -> 39398120
D18: Nd-147 | E18: ='AZ6 RZ1 (ACCIDENT)'!AX83 -> 3.4376125e+19 | F18: ='AZ6 RZ1 (ACCIDENT)'!AY83 -> 3.4376125e+19 | G18: ='AZ6 RZ1 (ACCIDENT)'!AZ83 -> 6.8752249e+17 | H18: ='AZ6 RZ1 (ACCIDENT)'!BA83 -> 3.4376125e+11 | I18: ='AZ6 RZ1 (ACCIDENT)'!BB83 -> 1.1458708e+10 | J18: ='AZ6 RZ1 (ACCIDENT)'!BC83 -> 1.1458708e+08 | K18: ='AZ6 RZ1 (ACCIDENT)'!BD83 -> 57293541
D19: Ce-144 | E19: ='AZ6 RZ1 (ACCIDENT)'!AX74 -> 3.4101167e+19 | F19: ='AZ6 RZ1 (ACCIDENT)'!AY74 -> 3.4101167e+19 | G19: ='AZ6 RZ1 (ACCIDENT)'!AZ74 -> 6.8202334e+17 | H19: ='AZ6 RZ1 (ACCIDENT)'!BA74 -> 3.4101167e+11 | I19: ='AZ6 RZ1 (ACCIDENT)'!BB74 -> 1.1367056e+10 | J19: ='AZ6 RZ1 (ACCIDENT)'!BC74 -> 1.1367056e+08 | K19: ='AZ6 RZ1 (ACCIDENT)'!BD74 -> 56835278
D20: Rh-105 | E20: ='AZ6 RZ1 (ACCIDENT)'!AX35 -> 3.2821619e+19 | F20: ='AZ6 RZ1 (ACCIDENT)'!AY35 -> 3.2821619e+19 | G20: ='AZ6 RZ1 (ACCIDENT)'!AZ35 -> 6.5643237e+17 | H20: ='AZ6 RZ1 (ACCIDENT)'!BA35 -> 3.2821619e+11 | I20: ='AZ6 RZ1 (ACCIDENT)'!BB35 -> 1.094054e+11 | J20: ='AZ6 RZ1 (ACCIDENT)'!BC35 -> 1.094054e+09 | K20: ='AZ6 RZ1 (ACCIDENT)'!BD35 -> 5.4702698e+08
D21: Pm-149 | E21: ='AZ6 RZ1 (ACCIDENT)'!AX65 -> 1.7762862e+19 | F21: ='AZ6 RZ1 (ACCIDENT)'!AY65 -> 1.7762862e+19 | G21: ='AZ6 RZ1 (ACCIDENT)'!AZ65 -> 3.5525724e+17 | H21: ='AZ6 RZ1 (ACCIDENT)'!BA65 -> 1.7762862e+11 | I21: ='AZ6 RZ1 (ACCIDENT)'!BB65 -> 5.9209541e+09 | J21: ='AZ6 RZ1 (ACCIDENT)'!BC65 -> 59209541 | K21: ='AZ6 RZ1 (ACCIDENT)'!BD65 -> 29604770
D22: Xe-135 | E22: ='AZ6 RZ1 (ACCIDENT)'!AX20 -> 1.5585413e+19 | F22: ='AZ6 RZ1 (ACCIDENT)'!AY20 -> 1.5585413e+19 | G22: ='AZ6 RZ1 (ACCIDENT)'!AZ20 -> 3.1170827e+18 | H22: ='AZ6 RZ1 (ACCIDENT)'!BA20 -> 1.5585413e+12 | I22: ='AZ6 RZ1 (ACCIDENT)'!BB20 -> 1.5585413e+12 | J22: ='AZ6 RZ1 (ACCIDENT)'!BC20 -> 1.5585413e+10 | K22: ='AZ6 RZ1 (ACCIDENT)'!BD20 -> 1.5585413e+10
D23: Ru-106 | E23: ='AZ6 RZ1 (ACCIDENT)'!AX33 -> 7.9247002e+18 | F23: ='AZ6 RZ1 (ACCIDENT)'!AY33 -> 7.9247002e+18 | G23: ='AZ6 RZ1 (ACCIDENT)'!AZ33 -> 1.58494e+17 | H23: ='AZ6 RZ1 (ACCIDENT)'!BA33 -> 7.9247002e+10 | I23: ='AZ6 RZ1 (ACCIDENT)'!BB33 -> 2.6415667e+10 | J23: ='AZ6 RZ1 (ACCIDENT)'!BC33 -> 2.6415667e+08 | K23: ='AZ6 RZ1 (ACCIDENT)'!BD33 -> 1.3207834e+08
D24: Pm-147 | E24: ='AZ6 RZ1 (ACCIDENT)'!AX64 -> 2.9669245e+18 | F24: ='AZ6 RZ1 (ACCIDENT)'!AY64 -> 2.9669245e+18 | G24: ='AZ6 RZ1 (ACCIDENT)'!AZ64 -> 5.933849e+16 | H24: ='AZ6 RZ1 (ACCIDENT)'!BA64 -> 2.9669245e+10 | I24: ='AZ6 RZ1 (ACCIDENT)'!BB64 -> 9.8897484e+08 | J24: ='AZ6 RZ1 (ACCIDENT)'!BC64 -> 9889748.4 | K24: ='AZ6 RZ1 (ACCIDENT)'!BD64 -> 4944874.2
D25: Cs-134 | E25: ='AZ6 RZ1 (ACCIDENT)'!AX50 -> 2.5676669e+18 | F25: ='AZ6 RZ1 (ACCIDENT)'!AY50 -> 2.5676669e+18 | G25: ='AZ6 RZ1 (ACCIDENT)'!AZ50 -> 2.5676669e+18 | H25: ='AZ6 RZ1 (ACCIDENT)'!BA50 -> 1.2838335e+12 | I25: ='AZ6 RZ1 (ACCIDENT)'!BB50 -> 4.2794449e+11 | J25: ='AZ6 RZ1 (ACCIDENT)'!BC50 -> 4.2794449e+09 | K25: ='AZ6 RZ1 (ACCIDENT)'!BD50 -> 2.1397224e+09
D26: Pu-241 | E26: ='AZ6 RZ1 (ACCIDENT)'!AX56 -> 1.6726319e+18 | F26: ='AZ6 RZ1 (ACCIDENT)'!AY56 -> 1.6726319e+18 | G26: ='AZ6 RZ1 (ACCIDENT)'!AZ56 -> 1.6726319e+16 | H26: ='AZ6 RZ1 (ACCIDENT)'!BA56 -> 8.3631594e+09 | I26: ='AZ6 RZ1 (ACCIDENT)'!BB56 -> 2.7877198e+08 | J26: ='AZ6 RZ1 (ACCIDENT)'!BC56 -> 2787719.8 | K26: ='AZ6 RZ1 (ACCIDENT)'!BD56 -> 1393859.9
D27: Cs-137 | E27: ='AZ6 RZ1 (ACCIDENT)'!AX15 -> 1.6033478e+18 | F27: ='AZ6 RZ1 (ACCIDENT)'!AY15 -> 1.6033478e+18 | G27: ='AZ6 RZ1 (ACCIDENT)'!AZ15 -> 1.6033478e+18 | H27: ='AZ6 RZ1 (ACCIDENT)'!BA15 -> 8.016739e+11 | I27: ='AZ6 RZ1 (ACCIDENT)'!BB15 -> 2.6722463e+11 | J27: ='AZ6 RZ1 (ACCIDENT)'!BC15 -> 2.6722463e+09 | K27: ='AZ6 RZ1 (ACCIDENT)'!BD15 -> 1.3361232e+09
D28: Sr-90 | E28: ='AZ6 RZ1 (ACCIDENT)'!AX61 -> 1.3069632e+18 | F28: ='AZ6 RZ1 (ACCIDENT)'!AY61 -> 1.3069632e+18 | G28: ='AZ6 RZ1 (ACCIDENT)'!AZ61 -> 1.3069632e+18 | H28: ='AZ6 RZ1 (ACCIDENT)'!BA61 -> 6.5348162e+12 | I28: ='AZ6 RZ1 (ACCIDENT)'!BB61 -> 2.1782721e+11 | J28: ='AZ6 RZ1 (ACCIDENT)'!BC61 -> 2.1782721e+09 | K28: ='AZ6 RZ1 (ACCIDENT)'!BD61 -> 1.089136e+09
D29: Eu-154 | E29: ='AZ6 RZ1 (ACCIDENT)'!AX91 -> 6.9158318e+16 | F29: ='AZ6 RZ1 (ACCIDENT)'!AY91 -> 6.9158318e+16 | G29: ='AZ6 RZ1 (ACCIDENT)'!AZ91 -> 6.9158318e+16 | H29: ='AZ6 RZ1 (ACCIDENT)'!BA91 -> 3.4579159e+11 | I29: ='AZ6 RZ1 (ACCIDENT)'!BB91 -> 1.1526386e+10 | J29: ='AZ6 RZ1 (ACCIDENT)'!BC91 -> 1.1526386e+08 | K29: ='AZ6 RZ1 (ACCIDENT)'!BD91 -> 57631931
D30: Eu-155 | E30: ='AZ6 RZ1 (ACCIDENT)'!AX92 -> 3.7303795e+16 | F30: ='AZ6 RZ1 (ACCIDENT)'!AY92 -> 3.7303795e+16 | G30: ='AZ6 RZ1 (ACCIDENT)'!AZ92 -> 3.7303795e+16 | H30: ='AZ6 RZ1 (ACCIDENT)'!BA92 -> 1.8651897e+11 | I30: ='AZ6 RZ1 (ACCIDENT)'!BB92 -> 6.2172992e+09 | J30: ='AZ6 RZ1 (ACCIDENT)'!BC92 -> 62172992 | K30: ='AZ6 RZ1 (ACCIDENT)'!BD92 -> 31086496
D31: Pu-238 | E31: ='AZ6 RZ1 (ACCIDENT)'!AX52 -> 2.9058508e+16 | F31: ='AZ6 RZ1 (ACCIDENT)'!AY52 -> 2.9058508e+16 | G31: ='AZ6 RZ1 (ACCIDENT)'!AZ52 -> 290585078439823 | H31: ='AZ6 RZ1 (ACCIDENT)'!BA52 -> 1.4529254e+08 | I31: ='AZ6 RZ1 (ACCIDENT)'!BB52 -> 4843084.6 | J31: ='AZ6 RZ1 (ACCIDENT)'!BC52 -> 48430.846 | K31: ='AZ6 RZ1 (ACCIDENT)'!BD52 -> 24215.423
D32: Sm-151 | E32: ='AZ6 RZ1 (ACCIDENT)'!AX88 -> 6.0573818e+15 | F32: ='AZ6 RZ1 (ACCIDENT)'!AY88 -> 6.0573818e+15 | G32: ='AZ6 RZ1 (ACCIDENT)'!AZ88 -> 121147636807935 | H32: ='AZ6 RZ1 (ACCIDENT)'!BA88 -> 60573818 | I32: ='AZ6 RZ1 (ACCIDENT)'!BB88 -> 2019127.3 | J32: ='AZ6 RZ1 (ACCIDENT)'!BC88 -> 20191.273 | K32: ='AZ6 RZ1 (ACCIDENT)'!BD88 -> 10095.636
D33: Pu-240 | E33: ='AZ6 RZ1 (ACCIDENT)'!AX54 -> 3.6760191e+15 | F33: ='AZ6 RZ1 (ACCIDENT)'!AY54 -> 3.6760191e+15 | G33: ='AZ6 RZ1 (ACCIDENT)'!AZ54 -> 3.6760191e+13 | H33: ='AZ6 RZ1 (ACCIDENT)'!BA54 -> 18380096 | I33: ='AZ6 RZ1 (ACCIDENT)'!BB54 -> 612669.86 | J33: ='AZ6 RZ1 (ACCIDENT)'!BC54 -> 6126.6986 | K33: ='AZ6 RZ1 (ACCIDENT)'!BD54 -> 3063.3493
D34: Pu-239 | E34: ='AZ6 RZ1 (ACCIDENT)'!AX53 -> 3.2926374e+15 | F34: ='AZ6 RZ1 (ACCIDENT)'!AY53 -> 3.2926374e+15 | G34: ='AZ6 RZ1 (ACCIDENT)'!AZ53 -> 3.2926374e+13 | H34: ='AZ6 RZ1 (ACCIDENT)'!BA53 -> 16463187 | I34: ='AZ6 RZ1 (ACCIDENT)'!BB53 -> 548772.9 | J34: ='AZ6 RZ1 (ACCIDENT)'!BC53 -> 5487.729 | K34: ='AZ6 RZ1 (ACCIDENT)'!BD53 -> 2743.8645
D35: Am-241 | E35: ='AZ6 RZ1 (ACCIDENT)'!AX58 -> 495255444127021 | F35: ='AZ6 RZ1 (ACCIDENT)'!AY58 -> 495255444127021 | G35: ='AZ6 RZ1 (ACCIDENT)'!AZ58 -> 4.9525544e+12 | H35: ='AZ6 RZ1 (ACCIDENT)'!BA58 -> 2476277.2 | I35: ='AZ6 RZ1 (ACCIDENT)'!BB58 -> 82542.574 | J35: ='AZ6 RZ1 (ACCIDENT)'!BC58 -> 825.42574 | K35: ='AZ6 RZ1 (ACCIDENT)'!BD58 -> 412.71287
D36: Am-243 | E36: ='AZ6 RZ1 (ACCIDENT)'!AX59 -> 231416878999564 | F36: ='AZ6 RZ1 (ACCIDENT)'!AY59 -> 231416878999564 | G36: ='AZ6 RZ1 (ACCIDENT)'!AZ59 -> 2.3141688e+12 | H36: ='AZ6 RZ1 (ACCIDENT)'!BA59 -> 1157084.4 | I36: ='AZ6 RZ1 (ACCIDENT)'!BB59 -> 38569.48 | J36: ='AZ6 RZ1 (ACCIDENT)'!BC59 -> 385.6948 | K36: ='AZ6 RZ1 (ACCIDENT)'!BD59 -> 192.8474
D37: Tc-99 | E37: ='AZ6 RZ1 (ACCIDENT)'!AX27 -> 197430763636864 | F37: ='AZ6 RZ1 (ACCIDENT)'!AY27 -> 197430763636864 | G37: ='AZ6 RZ1 (ACCIDENT)'!AZ27 -> 3.9486153e+12 | H37: ='AZ6 RZ1 (ACCIDENT)'!BA27 -> 1974307.6 | I37: ='AZ6 RZ1 (ACCIDENT)'!BB27 -> 658102.55 | J37: ='AZ6 RZ1 (ACCIDENT)'!BC27 -> 6581.0255 | K37: ='AZ6 RZ1 (ACCIDENT)'!BD27 -> 3290.5127
D38: Zr-93 | E38: ='AZ6 RZ1 (ACCIDENT)'!AX68 -> 2.7371987e+13 | F38: ='AZ6 RZ1 (ACCIDENT)'!AY68 -> 2.7371987e+13 | G38: ='AZ6 RZ1 (ACCIDENT)'!AZ68 -> 5.4743973e+11 | H38: ='AZ6 RZ1 (ACCIDENT)'!BA68 -> 273719.87 | I38: ='AZ6 RZ1 (ACCIDENT)'!BB68 -> 91239.955 | J38: ='AZ6 RZ1 (ACCIDENT)'!BC68 -> 912.39955 | K38: ='AZ6 RZ1 (ACCIDENT)'!BD68 -> 456.19978
D39: Pu-242 | E39: ='AZ6 RZ1 (ACCIDENT)'!AX57 -> 2.343488e+13 | F39: ='AZ6 RZ1 (ACCIDENT)'!AY57 -> 2.343488e+13 | G39: ='AZ6 RZ1 (ACCIDENT)'!AZ57 -> 2.343488e+11 | H39: ='AZ6 RZ1 (ACCIDENT)'!BA57 -> 117174.4 | I39: ='AZ6 RZ1 (ACCIDENT)'!BB57 -> 3905.8133 | J39: ='AZ6 RZ1 (ACCIDENT)'!BC57 -> 39.058133 | K39: ='AZ6 RZ1 (ACCIDENT)'!BD57 -> 19.529067
D40: Cs-135 | E40: ='AZ6 RZ1 (ACCIDENT)'!AX13 -> 6.3414659e+12 | F40: ='AZ6 RZ1 (ACCIDENT)'!AY13 -> 6.3414659e+12 | G40: ='AZ6 RZ1 (ACCIDENT)'!AZ13 -> 6.3414659e+12 | H40: ='AZ6 RZ1 (ACCIDENT)'!BA13 -> 3170732.9 | I40: ='AZ6 RZ1 (ACCIDENT)'!BB13 -> 1056911 | J40: ='AZ6 RZ1 (ACCIDENT)'!BC13 -> 10569.11 | K40: ='AZ6 RZ1 (ACCIDENT)'!BD13 -> 5284.5549
D41: U-236 | E41: ='AZ6 RZ1 (ACCIDENT)'!AX81 -> 5.6844437e+12 | F41: ='AZ6 RZ1 (ACCIDENT)'!AY81 -> 5.6844437e+12 | G41: ='AZ6 RZ1 (ACCIDENT)'!AZ81 -> 5.6844437e+10 | H41: ='AZ6 RZ1 (ACCIDENT)'!BA81 -> 28422.219 | I41: ='AZ6 RZ1 (ACCIDENT)'!BB81 -> 947.40728 | J41: ='AZ6 RZ1 (ACCIDENT)'!BC81 -> 9.4740728 | K41: ='AZ6 RZ1 (ACCIDENT)'!BD81 -> 4.7370364
D42: Np-237 | E42: ='AZ6 RZ1 (ACCIDENT)'!AX47 -> 4.4098293e+12 | F42: ='AZ6 RZ1 (ACCIDENT)'!AY47 -> 4.4098293e+12 | G42: ='AZ6 RZ1 (ACCIDENT)'!AZ47 -> 4.4098293e+10 | H42: ='AZ6 RZ1 (ACCIDENT)'!BA47 -> 22049.147 | I42: ='AZ6 RZ1 (ACCIDENT)'!BB47 -> 734.97156 | J42: ='AZ6 RZ1 (ACCIDENT)'!BC47 -> 7.3497156 | K42: ='AZ6 RZ1 (ACCIDENT)'!BD47 -> 3.6748578
D43: U-238 | E43: ='AZ6 RZ1 (ACCIDENT)'!AX45 -> 1.2339234e+12 | F43: ='AZ6 RZ1 (ACCIDENT)'!AY45 -> 1.2339234e+12 | G43: ='AZ6 RZ1 (ACCIDENT)'!AZ45 -> 1.2339234e+10 | H43: ='AZ6 RZ1 (ACCIDENT)'!BA45 -> 6169.6172 | I43: ='AZ6 RZ1 (ACCIDENT)'!BB45 -> 205.65391 | J43: ='AZ6 RZ1 (ACCIDENT)'!BC45 -> 2.0565391 | K43: ='AZ6 RZ1 (ACCIDENT)'!BD45 -> 1.0282695
D44: Pd-107 | E44: ='AZ6 RZ1 (ACCIDENT)'!AX10 -> 1.0578351e+12 | F44: ='AZ6 RZ1 (ACCIDENT)'!AY10 -> 1.0578351e+12 | G44: ='AZ6 RZ1 (ACCIDENT)'!AZ10 -> 1.0578351e+12 | H44: ='AZ6 RZ1 (ACCIDENT)'!BA10 -> 1.0578351e+10 | I44: ='AZ6 RZ1 (ACCIDENT)'!BB10 -> 1.0578351e+10 | J44: ='AZ6 RZ1 (ACCIDENT)'!BC10 -> 1.0578351e+08 | K44: ='AZ6 RZ1 (ACCIDENT)'!BD10 -> 52891757
...
